Workbook
Name Addr_Country: Iniciar!$Q$48
Name Addr_Mail: 'Modelo Energético'!$G$1307
Name Addr_Manufacturer: 'Modelo Energético'!$E$1307
Name Addr_Model: 'Modelo Energético'!$F$1307
Name Addr_ProductType: 'Modelo Energético'!$C$1307
Name Addr_Province: Iniciar!$R$48
Name Addr_PVManufacturer: 'Modelo Energético'!$Z$1329
Name Addr_PVModel: 'Modelo Energético'!$AA$1329
Name Addr_PVType: 'Modelo Energético'!$AD$1329
Name Addr_Region: 'Modelo Energético'!$AB$1329
Name Addr_Station: Iniciar!$S$48
Name Addr_type: 'Modelo Energético'!$S$474
Name Addr_Web: 'Modelo Energético'!$H$1307
Name AfterIRR: 'Análise Financeira'!$AA$63
Name AnalType: Iniciar!$D$28
Name Ann_costs: 'Análise Financeira'!$K$22
Name Ann_heat_deg_days: 'Carga e Rede'!$AI$5
Name Ann_sav: 'Análise Financeira'!$K$36
Name AnnEarthTempAmp: Iniciar!$D$54
Name AnnEarthTempAmpUnit: Iniciar!$V$52
Name AtmosPressure_Jan: Iniciar!$G$58
Name AvgAtmosPressUnit: Iniciar!$T$54
Name AvgDailyRadiation_Jan: Iniciar!$F$58
Name AvgDailyRadUnit: Iniciar!$T$55
Name AvgTemp_Jan: Iniciar!$D$58
Name avgTempUnit: Iniciar!$R$50
Name AvgWindSpeed_Jan: Iniciar!$H$58
Name AvgWindSpeedUnit: Iniciar!$T$53
Name BatMismatch: 'Modelo Energético '!$D$266
Name BatTemp: 'Modelo Energético '!$R$264:$R$266
Name BatTempCtrl: 'Modelo Energético '!$D$263
Name BatTempIndex: 'Modelo Energético '!$M$264
Name Bench_area: 'Modelo Energético '!$A$183:$A$188
Name Bench_ref: 'Modelo Energético '!$C$181
Name Bench_ref2: 'Modelo Energético '!$J$1173
Name CA_all: 'Análise de Custos'!$I$1:$M$1
Name CA_Balance: 'Análise de Custos'!$D$100
Name CA_BPlist_sort: 'Análise de Custos'!$H$261
Name CA_BPlist1: 'Análise de Custos'!$F$261:$F$272
Name CA_BPlist2: 'Análise de Custos'!$H$261:$H$272
Name CA_Canada: 'Análise de Custos'!$K$1:$L$1
Name CA_CapacityUnit: 'Análise de Custos'!$E$46,'Análise de Custos'!$D$74:$D$78,'Análise de Custos'!$D$87:$D$89
Name CA_CoolingHelp: 'Análise de Custos'!$L$87
Name CA_Costcells: 'Análise de Custos'!$F$11:$G$20,'Análise de Custos'!$F$23:$G$213,'Análise de Custos'!$G$215:$G$227,'Análise de Custos'!$F$254:$G$256
Name CA_Costcells2: 'Análise de Custos'!$G$229:$G$251
Name CA_Costcells3: 'Análise de Custos'!$F$215:$F$224
Name CA_Costcells31: 'Análise de Custos'!$F$229:$F$250
Name CA_country1: 'Análise de Emissões'!$D$341:$D$589
Name CA_country2: 'Análise de Emissões'!$C$341:$C$589
Name CA_country2sort: 'Análise de Emissões'!$C$341
Name CA_CS: 'Análise de Custos'!$O$14
Name CA_fuelBC: 'Análise de Custos'!$O$227
Name CA_fuelPC: 'Análise de Custos'!$O$214
Name CA_Heatinghelp: 'Análise de Custos'!$L$74
Name CA_HS: 'Análise de Custos'!$O$12
Name CA_IC: 'Análise de Custos'!$O$15
Name CA_link: 'Análise de Custos'!$D$258
Name CA_Month: 'Análise de Custos'!$E$197
Name CA_new1: 'Análise de Custos'!$M$1:$M$1
Name CA_OMS: 'Análise de Custos'!$O$203

Sheet Parameter
A1: PARAMETERS TABLE
A2: MODULE | B2: NAME | C2: VALUE | D2: (comments)
A3: model version | B3: modelVersion | C3: =Iniciar!B80 -> RETScreen4 2012-06-01 | D3: Model version take from Start!B80
A4: Start worksheet
B5: unit | C5: 1 | D5: project name
B6: projectName | C6: =IF(TRIM(Iniciar!D14) = "","RETScreen",Iniciar!D14) -> Estudo de Caso Foto Voltaico | D6: project location
B7: projectLocation | C7: =Iniciar!D15 -> 0
B8: preparedFor | C8: =Iniciar!D17 -> 0
B9: preparedBy | C9: =Iniciar!D18 -> 0
B10: projectType | C10: =EM_Projtype_V -> Produção de eletricidade
B11: gridType | C11: =Set_GridType -> Rede Central
B12: heatingValueRef | C12: =Iniciar!D30 -> Poder Calorífico Inferior (PCI) | D12: A copy of the language value show in the start sheet, use in case of a DB error
B13: languageShow | C13: Portuguese - Português | D13: The value of the language as see in the start sheet
B14: language | C14: Portuguese
B15: userManual | C15: =OnlineManualLanguage -> English - Anglais | D15: Name or symbol of the currency
B16: Currency_name | C16: =Currency_name -> Euro | D16: The name of the technology to show in the Project Form
B17: projectTech | C17: 41061
B18: SaveDate | C18: 39758
B19: ActiveMap | C19: Public release 2008-12-09
B20: projectCurrency | C20: =IF(Iniciar!D37=Language!C80,0,1) -> 0 | D20: 0 --> metric 1-->imperial
B21: elevationUnitFactor | C21: =Iniciar!N51 -> 1
B22: heatingTempUnitFactor | C22: =Iniciar!N52 -> 1
B23: coolongTempUnitFactor | C23: =Iniciar!N53 -> 1
B24: earthTempAmpUnitFactor | C24: =Iniciar!N54 -> 1
B25: airTempUnitFactor | C25: =Iniciar!O56 -> 1
B26: earthTempUnitFactor | C26: =Iniciar!S56 -> 1
B27: solarUnitFactor | C27: =Iniciar!P56 -> 1
B28: atmPressureUnitFactor | C28: =Iniciar!Q56 -> 1
B29: windSpeedUnitFactor | C29: =Iniciar!R56 -> 1
B30: heatingDegreeDaysUnitFactor | C30: =Iniciar!T56 -> 1
B31: coolingDegreeDaysUnitFactor | C31: =Iniciar!U56 -> 1
B32: lastHelpFilePath
B33: isFirstRun | C33: TRUE
A36: hydro form | B36: hydroPastedCountry | C36: 35 | D36: the last Country ID pasted by the hydro form
B37: hydroPastedProvince | D37: the last provice ID pasted by the hydro form
B38: hydroPastedCurveType | C38: AA1 | D38: the last curve type ID pasted by the hydro form
B39: hydroPastedGaugeName | C39: 207 | D39: the last gauge ID pasted by the hydro form
A41: Others unit … | B41: lastRETFilePath | D41: The last valid path for the user's .ret file (note: default RETScreen.ret file in defaultDBPath)
B42: defaultRETName | D42: the name of the .ret file with all the default projects/case studies
B43: defaultRETPath | D43: Last valid path for the default Project DB file… should be the same as defaultDBPath when first installed
...

Sheet Iniciar
W1: 30000
A2: =Language!C848 -> Software de Análise de Projetos de Energia Limpa | N2: =IF(ISERROR(SUM(N3:O28)+P20),1,SUM(N3:O28)+P20) -> 20933 | O2: 20933 | W2: 30000
P3: =IF(ISERROR(VLOOKUP(Set_OpenClose,N149:R368,5,FALSE)),0,VLOOKUP(Set_OpenClose,N149:R368,5,FALSE)) -> 0 | Q3: Fuel calc source | W3: 30000
C4: =Language!C1910 -> Informação sobre o projeto | D4: =Language!C1962 -> Veja banco de Dados do projeto | P4: =IF(ISERROR(VLOOKUP(Set_OpenClose,N149:O368,2,FALSE)),0,VLOOKUP(Set_OpenClose,N149:O368,2,FALSE)) -> 0 | Q4: 0 | R4: EE_type | W4: 6000000
R5: 1 | S5: =Set_T1 -> Sistema à biomassa | W5: 31000
W6: 30000
C7: =C32 -> Idioma | D7: Portuguese - Português | W7: 30000
W8: 30000
C9: =VLOOKUP($D$7,$H$83:$K$118,2,FALSE) -> Observaçao importante | W9: 30000
B10: =VLOOKUP($D$7,$H$83:$K$118,4,FALSE) -> O software RETScreen utiliza macros do Excel. Devido aos parâmetros de segurança de macros definidos em alguns computadores, você poderá ter que habilitar macros quando abrir o arquivo RETScreen no Excel. | W10: 30000
W11: 30000
B12: =VLOOKUP($D$7,$H$83:$K$118,3,FALSE) -> Além disso, em alguns computadores, o nível de segurança de macros do Excel é automaticamente definido como "muito alto" . Neste caso você terá que redefinir o nível de segurança para "médio" ou "alto" usando o Menu em "Ferramentas, Macro, Nível de segurança..." antes de usar o RETScreen. Caso isto não seja feito o software não funcionará corretamente. | W12: 30000
W13: 30000
C14: =Language!C181 -> Nome do Projeto | D14: Estudo de Caso Foto Voltaico | R14: 2 | S14: =Set_T2 -> Fotovoltaica | W14: 31002
C15: =Language!C182 -> Localização do Projeto | R15: 3 | S15: =Set_T3 -> Bomba de calor | W15: 31004
R16: 4 | S16: =Equip_PowerType -> Fotovoltaica | W16: 31000
C17: =Language!C1904 -> Preparado para | R17: 5 | S17: =Equip_PowerType&" - "&Equip_CoolType -> Fotovoltaica - Bomba de calor | W17: 31006
C18: =Language!C1903 -> Preparado por | P18: RETScreen4.xls - 1:27:08 PM - 6/1/2012 | R18: 6 | S18: =Equip_HeatingType&" - "&Equip_CoolType -> Sistema à biomassa - Bomba de calor | W18: 31008
R19: 7 | S19: =Equip_PowerType&" - "&Equip_CoolType -> Fotovoltaica - Bomba de calor | W19: 31000
C20: =Language!C1911 -> Tipo de projeto | D20: Produção de eletricidade | N20: =IF(D20="",1,IF(MATCH(D20,B107:B116,0)=10,2,MATCH(D20,B107:B116,0))) -> 2 | P20: =IF(D20="",1,MATCH(D20,B107:B116,0)) -> 2 | R20: 8 | S20: =D22 -> Industrial | W20: 31010
Q21: =VLOOKUP(P20,R5:S22,2) -> Fotovoltaica | R21: 9 | S21: =IF(EE_UserCode=1,'Modelo Energético '!D933,IF(EE_UserCode=2,'Modelo Energético '!D934,G111)) -> Energia | W21: 31000
C22: =Language!C1647 -> Tipo de instalação | D22: Industrial | N22: =IF(D22="",1,MATCH(D22,G107:G111,0)) -> 4 | P22: =IF(HideCode_projectType=8,1,0) -> 0 | R22: 10 | S22: =Equip_PowerType&" - "&Equip_PowerTypeInter -> Fotovoltaica - Turbina à gas | W22: 31012
C23: =Language!C2015 -> Tecnologia | D23: Sistema à biomassa | N23: =IF(OR(HideCode_projectType<>1,D23=""),0,MATCH(D23,C107:C114,0)) -> 0 | W23: 31014
C24: =$C$23 -> Tecnologia | D24: Fotovoltaica | N24: =IF(OR(HideCode_projectType<>2,D24=""),0,IF(P20=10,0,MATCH(D24,D107:D121,0))) -> 9 | W24: 31014
C25: =$C$23 -> Tecnologia | D25: Bomba de calor | N25: =IF(OR(HideCode_projectType<>3,D25=""),0,MATCH(D25,E107:E112,0)) -> 0 | W25: 31014
C26: =Language!C586 -> Tipo de grid | D26: Rede Central | N26: =O26 -> 1 | O26: =IF(OR(N20=1,N20=3,N20=6,N20>7),0,IF(Set_GridType="",1,MATCH(Set_GridType,LN_GridType,0))) -> 1 | W26: 31016
W27: 31000
C28: =Language!C1476 -> Tipo de análise | D28: Método 2 | N28: =IF(D28="",2,MATCH(D28,E127:E128,0)) -> 2 | O28: =Q28+N28 -> 20912 | Q28: =N20*10000+(N23+N24+N25)*100+N26*10 -> 20910 | W28: 31018
W29: 31000
C30: =Language!C1723 -> Poder calorífico de referência | D30: Poder Calorífico Inferior (PCI) | W30: 31020
C31: =Language!C1972 -> Ver parâmetros | N31: TRUE | W31: 31022
C32: =Language!C177 -> Idioma | D32: Portuguese - Português | N32: =IF(D32="",1,MATCH(D32,H83:H118,0)) -> 23 | W32: 31024
C33: =Language!C2614 -> Manual do usuário | D33: English - Anglais | N33: =IF(OnlineManualLanguage=B125,"RETScreen4F.chm","RETScreen4.chm") -> RETScreen4.chm | W33: 31026
W34: 31000
C35: =Language!C495 -> Moeda | D35: Euro | N35: =IF(Currency_name="",1,MATCH(Currency_name,currency_list,0)) -> 2 | O35: 1 | W35: 31028
C36: =Language!C497 -> Símbolo | W36: 31030
C37: =Language!C178 -> Unidades | D37: Unidades métricas | N37: =IF(OR(D37=B127,D37=""),TRUE,FALSE) -> TRUE | W37: 31032
N38: =IF(OR(D30=C127,D30=""),1,2) -> 2 | W38: 31000
W39: 32000
B40: =Language!C179 -> Condições de Referência do site | D40: =Language!C1964 -> Selecionar local de dados climáticos | W40: 32000
...

Sheet Carga e Rede
A1: =Language!C867&'Análise de Emissões'!B188 -> RETScreen Proj. Rede e Carga - Projeto produção de Eletricidade | BA1: 40000
U2: =IF(ISERROR(SUM(U3:V254)+HideCodeEM_1),7,SUM(U3:V254)+HideCodeEM_1) -> 20984 | V2: 80078 | W2: SI units | X2: SI values | Y2: IP units | Z2: IP values | BA2: 40000
BA3: 40000
A4: =Language!C243 -> Projeto do Sistema de Aquecimento | C4: =Language!C180 -> Unidade | BA4: 41000
AG5: =Language!C245 -> Graus-dias anual de aquecimento abaixo 18°C | AH5: =Language!C1311 -> °C-d | AI5: =SUM(Iniciar!T58:T69) -> 1188.3 | BA5: 41000
A6: =Language!C275 -> Sistema de Aquecimento para caso de referência | C6: Prédio individual - aquecimento ambiente | U6: =IF(C6="",1,MATCH(C6,LN_heatsystem,0)) -> 1 | V6: =HideCode_projectType -> 2 | AH6: =Language!C1339 -> h | AI6: =J336 -> 0 | BA6: 41200
BA7: 41200
B8: =Language!C276 -> Área de piso aquecido para o prédio | C8: m² | W8: m² | X8: =IF(C8=$D$260,D8,D8*$E$261) -> 0 | BA8: 41302
B9: =Language!C211 -> Tipo de Combustível | D9: Gas natural - m³ | BA9: 2010106
B10: =Language!C219 -> Eficiência Sazonal | C10: =$C$13 -> % | BA10: 2020208
B11: =Language!C277 -> Cálculo carga p/ aquecimento | BA11: 41400
B12: =Language!C278 -> Carga p/ aquecimento do prédio | C12: W/m² | W12: W/m² | X12: =IF(C12=$D$266,D12,D12*$E$267) -> 0 | BA12: 41402
B13: =Language!C246 -> Demanda base calor p/ rede água quente | C13: =Language!C1306 -> % | BA13: 41403
B14: =Language!C279 -> Carga de ponta p/ aquecimento do processo | C14: kW | W14: kWth | X14: =IF(C14=$D$269,D14,D14/$E$270) -> 0 | BA14: 41404
B15: =Language!C280 -> Características da carga de aquecimento do processo | D15: Padrão | U15: =IF(D15="",1,MATCH(D15,LN_SD,0)) -> 1 | BA15: 41406
B16: =Language!C281 -> Horas equivalentes à plena carga - aquecimento do processo | C16: =$AH$6 -> h | D16: =IF(HideCodeLN_HPT=2,AI6,H336) -> 0 | F16: =Language!C59 -> Completar as cargas mensais do processo | W16: =IF(U15=2,1,IF(D17=0,0,1)) -> 0 | BA16: 41408
B17: =B16 -> Horas equivalentes à plena carga - aquecimento do processo | C17: =$AH$6 -> h | BA17: 41408
B18: =Language!C282 -> Demanda aquecimento ambiente | C18: =IF(Unit=TRUE,Language!C1396,Language!C1382) -> MWh | D18: =IF(Unit=TRUE,X18,Z18) -> 0 | W18: MWh | X18: =IF(X12=0,0,IF(X8=0,"-",E335)) -> 0 | Y18: million Btu | Z18: =X18*$F$270 -> 0 | BA18: 41410
B19: =Language!C283 -> Demanda p/ aquecimento do processo | C19: =C18 -> MWh | D19: =IF(Unit=TRUE,X19,Z19) -> 0 | W19: MWh | X19: =G335+I335 -> 0 | Y19: million Btu | Z19: =X19*$F$270 -> 0 | BA19: 41412
B20: =Language!C284 -> Demanda total p/ aquecimento | C20: =C18 -> MWh | D20: =IF(Unit=TRUE,X20,Z20) -> 0 | W20: MWh | X20: =IF(HideCodeLN_HPT=2,X19,IF(HideCodeLN_HPT=1,X18,IF(HideCodeLN_HPT=3,X19+X18,0))) -> 0 | Y20: million Btu | Z20: =X20*$F$270 -> 0 | BA20: 41414
B21: =Language!C285 -> Carga total p/ aquecimento de ponta | C21: =IF(Unit=TRUE,Language!C1364,Language!C1383) -> kW | D21: =IF(Unit=TRUE,X21,Z21) -> 0 | W21: kW | X21: =IF(HideCodeLN_HPT=1,X8*X12/1000,IF(HideCodeLN_HPT=2,X14*W16,X8*X12/1000+X14*W16)) -> 0 | Y21: million Btu/h | Z21: =X21*$E$270 -> 0 | BA21: 41416
B22: =Language!C286 -> Consumo de combustível - anual | C22: =VLOOKUP($D$9,$E$340:$I$360,3,FALSE) -> m³ | D22: =IF(OR(D10="",D10=0),0,X$20/VLOOKUP($D$9,E340:I360,4,FALSE)*1000/D$10) -> 0 | BA22: 41420
B23: =Language!C212 -> Preço do combustível | C23: =VLOOKUP($D$9,$E$340:$I$360,5,FALSE) -> €/m³ | BA23: 2010108
B24: =Language!C287 -> Custo do combustível | D24: =IF(D$9=$E$344,D23*D22*1000,IF(D$9=$E$360,D23*D22,D23*D22)) -> 0 | BA24: 5097210
A25: =A52 -> Ações de eficiência energética do caso proposto | BA25: 41500
B26: =Language!C289 -> Ações de eficiência energética no uso final | C26: =$C$13 -> % | BA26: 41501
B27: =Language!C290 -> Carga líquida de aquecimento de ponta | C27: =C21 -> kW | D27: =IF(Unit=TRUE,X27,Z27) -> 0 | W27: kW | X27: =MAX(P230:P244) -> 0 | Y27: million Btu/h | Z27: =X27*$E$270 -> 0 | BA27: 41502
B28: =Language!C291 -> Demanda líquida de aquecimento | C28: =C18 -> MWh | D28: =IF(Unit=TRUE,X28,Z28) -> 0 | W28: MWh | X28: =(SUMPRODUCT(C321:C332,P230:P241)+P244*C333)/1000 -> 0 | Y28: million Btu | Z28: =X28*$F$270 -> 0 | BA28: 41504
BA29: 41000
B30: =IF(HideCodeLN_HPT>6,Language!C292,"") | F30: =IF(HideCodeLN_HPT>6,Language!C293,Language!C294) -> Zonas do Prédio | BA30: 41202
F31: 1 | G31: 2 | H31: 3 | I31: 4 | J31: 5 | K31: 6 | L31: 7 | M31: 8 | N31: 9 | O31: 10 | P31: 11 | Q31: 12 | R31: 13 | S31: 14 | BA31: 41302
B32: =IF(HideCodeLN_HPT>6,Language!C295,Language!C297) -> Área de piso aquecido por zona | C32: m² | D32: =IF(C32=$D$260,X32,Z32) -> 1 | F32: 1 | T32: 1 | W32: m² | X32: =SUM(AH32:AU32) -> 1 | Y32: ft² | Z32: =X32/$E$261 -> 10.76391 | AH32: =IF($C32=$D$260,F32,F32*$E$261) -> 1 | AI32: =IF($C32=$D$260,G32,G32*$E$261) -> 0 | AJ32: =IF($C32=$D$260,H32,H32*$E$261) -> 0 | AK32: =IF($C32=$D$260,I32,I32*$E$261) -> 0 | AL32: =IF($C32=$D$260,J32,J32*$E$261) -> 0 | AM32: =IF($C32=$D$260,K32,K32*$E$261) -> 0 | AN32: =IF($C32=$D$260,L32,L32*$E$261) -> 0 | AO32: =IF($C32=$D$260,M32,M32*$E$261) -> 0 | ... AU32: =IF($C32=$D$260,S32,S32*$E$261) -> 0 | BA32: 41302
B33: =Language!C296 -> Número de prédios no condomínio | C33: =Language!C1309 -> prédio | D33: =SUMIF(AH32:AU32,">0",F33:S33) -> 1 | F33: 1 | BA33: 41312
B34: =B9 -> Tipo de Combustível | F34: Gas natural - m³ | G34: Gas natural - m³ | H34: Gas natural - m³ | I34: Gas natural - m³ | J34: Gas natural - m³ | K34: Gas natural - m³ | L34: Gas natural - m³ | M34: Gas natural - m³ | N34: Gas natural - m³ | O34: Gas natural - m³ | P34: Gas natural - m³ | Q34: Gas natural - m³ | R34: Gas natural - m³ | S34: Gas natural - m³ | BA34: 2010106
B35: =B10 -> Eficiência Sazonal | C35: =$C$13 -> % | D35: - | BA35: 2020208
B36: =Language!C277 -> Cálculo carga p/ aquecimento | BA36: 41400
B37: =IF(HideCodeLN_HPT>6,Language!C298,Language!C299) -> Carga de aquecimento por zona | C37: W/m² | D37: - | AH37: =IF($C37=$D$266,F37,F37*$E$267) -> 0 | AI37: =IF($C37=$D$266,G37,G37*$E$267) -> 0 | AJ37: =IF($C37=$D$266,H37,H37*$E$267) -> 0 | AK37: =IF($C37=$D$266,I37,I37*$E$267) -> 0 | AL37: =IF($C37=$D$266,J37,J37*$E$267) -> 0 | AM37: =IF($C37=$D$266,K37,K37*$E$267) -> 0 | AN37: =IF($C37=$D$266,L37,L37*$E$267) -> 0 | AO37: =IF($C37=$D$266,M37,M37*$E$267) -> 0 | ... AU37: =IF($C37=$D$266,S37,S37*$E$267) -> 0 | BA37: 41402
B38: =B13 -> Demanda base calor p/ rede água quente | C38: =$C$13 -> % | BA38: 41403
B39: =Language!C279 -> Carga de ponta p/ aquecimento do processo | C39: kW | D39: =IF(C39=D269,X39,Z39) -> 0 | W39: kW | X39: =IF(U40=2,SUM(AH39:AU39),SUMIF(F42:S42,">0",AH39:AU39)) -> 0 | Y39: million Btu/h | Z39: =X39*$E$270 -> 0 | AG39: =AG44/X39*1000 -> #DIV/0! | AH39: =IF(OR(AH32=0,AH32=""),0,1)*IF($C39=$D$269,F39,F39/$E$270) -> 0 | AI39: =IF(OR(AI32=0,AI32=""),0,1)*IF($C39=$D$269,G39,G39/$E$270) -> 0 | AJ39: =IF(OR(AJ32=0,AJ32=""),0,1)*IF($C39=$D$269,H39,H39/$E$270) -> 0 | AK39: =IF(OR(AK32=0,AK32=""),0,1)*IF($C39=$D$269,I39,I39/$E$270) -> 0 | AL39: =IF(OR(AL32=0,AL32=""),0,1)*IF($C39=$D$269,J39,J39/$E$270) -> 0 | AM39: =IF(OR(AM32=0,AM32=""),0,1)*IF($C39=$D$269,K39,K39/$E$270) -> 0 | AN39: =IF(OR(AN32=0,AN32=""),0,1)*IF($C39=$D$269,L39,L39/$E$270) -> 0 | AO39: =IF(OR(AO32=0,AO32=""),0,1)*IF($C39=$D$269,M39,M39/$E$270) -> 0 | ... AU39: =IF(OR(AU32=0,AU32=""),0,1)*IF($C39=$D$269,S39,S39/$E$270) -> 0 | BA39: 41404
B40: =Language!C280 -> Características da carga de aquecimento do processo | D40: Padrão | U40: =IF(D40="",1,MATCH(D40,LN_SD,0)) -> 1 | AG40: Space kW elect | AH40: =IF(F34=$E$344,IF(OR(F32=0,F35=0,HideCodeLN_HPT=5,HideCodeLN_HPT=8),0,AH32*AH37/F35/1000),0) -> 0 | AI40: =IF(G34=$E$344,IF(OR(G32=0,G35=0,HideCodeLN_HPT=5,HideCodeLN_HPT=8),0,AI32*AI37/G35/1000),0) -> 0 | AJ40: =IF(H34=$E$344,IF(OR(H32=0,H35=0,HideCodeLN_HPT=5,HideCodeLN_HPT=8),0,AJ32*AJ37/H35/1000),0) -> 0 | AK40: =IF(I34=$E$344,IF(OR(I32=0,I35=0,HideCodeLN_HPT=5,HideCodeLN_HPT=8),0,AK32*AK37/I35/1000),0) -> 0 | AL40: =IF(J34=$E$344,IF(OR(J32=0,J35=0,HideCodeLN_HPT=5,HideCodeLN_HPT=8),0,AL32*AL37/J35/1000),0) -> 0 | AM40: =IF(K34=$E$344,IF(OR(K32=0,K35=0,HideCodeLN_HPT=5,HideCodeLN_HPT=8),0,AM32*AM37/K35/1000),0) -> 0 | AN40: =IF(L34=$E$344,IF(OR(L32=0,L35=0,HideCodeLN_HPT=5,HideCodeLN_HPT=8),0,AN32*AN37/L35/1000),0) -> 0 | AO40: =IF(M34=$E$344,IF(OR(M32=0,M35=0,HideCodeLN_HPT=5,HideCodeLN_HPT=8),0,AO32*AO37/M35/1000),0) -> 0 | ... AU40: =IF(S34=$E$344,IF(OR(S32=0,S35=0,HideCodeLN_HPT=5,HideCodeLN_HPT=8),0,AU32*AU37/S35/1000),0) -> 0 | BA40: 41406
...

Sheet Modelo Energético 
A1: =Language!C866&'Análise de Emissões'!B188 -> Modelo Energético RETScreen - Projeto produção de Eletricidade | M1: =IF(ISERROR(SUM(M4:M1015)+HideCodeEM_1),6,SUM(M4:M1015)+HideCodeEM_1) -> 30881.192 | N1: 2000000 | Q1: 82490 | R1: =Set_Level -> 2 | S1: 1 | Z1: RadioButtons | AA1: row | AB1: col | AC1: lrow | AD1: lcol | AE1: value | AF1: group | AG1: mLine | AH1: srow | AI1: scol | AJ1: nextRow | AK1: nextCol | AO1: CheckBox | AP1: row | AQ1: columns | AR1: link row | AS1: link column | AT1: srow | AU1: scolumn
N2: 2000000 | R2: =Iniciar!P4 -> 0 | S2: 1 | AA2: 204 | AB2: 3 | AC2: 204 | AD2: 17 | AE2: TRUE | AF2: EE12-1 | AG2: TRUE | AH2: 204 | AI2: 4 | AJ2: 205 | AK2: 17 | AP2: 4 | AQ2: 3 | AR2: 4 | AS2: 13 | AT2: 4 | AU2: 4
A3: ='Análise de Emissões'!B188 -> Projeto produção de Eletricidade | N3: 2000000 | Q3: Project Type | R3: =HideCode_projectType -> 2 | AA3: 204 | AB3: 3 | AC3: 205 | AD3: 17 | AE3: TRUE | AF3: EE12-1 | AG3: TRUE | AH3: 204 | AI3: 4 | AJ3: 204 | AK3: 17 | AP3: 37 | AQ3: 3 | AR3: 37 | AS3: 13 | AT3: 37 | AU3: 4
A4: =Language!C1695 -> Combustíveis & horários | C4: þ | D4: =$G$384 -> Mostrar dado | M4: TRUE | N4: 4010000 | Q4: Latitude of project location | S4: °N | T4: =Iniciar!E49 -> 40.2 | U4: =T4*PI()/180 -> 0.70162236 | AA4: 543 | AB4: 3 | AC4: 542 | AD4: 17 | AE4: TRUE | AF4: EEM_SAH | AG4: FALSE | AP4: 39 | AQ4: 10 | AR4: 39 | AS4: 17 | AT4: 38 | AU4: 10
M5: =IF(EE1_Show1=TRUE,99,79) -> 99 | N5: 4010000 | AA5: 544 | AB5: 3 | AC5: 543 | AD5: 17 | AE5: TRUE | AF5: EEM_SAH | AG5: FALSE | AP5: 41 | AQ5: 10 | AR5: 41 | AS5: 17 | AT5: 41 | AU5: 9
B6: =Language!C574 -> Combustível | E6: =$B$801&" 1" -> Tipo de Combustível 1 | F6: =$B$801&" 2" -> Tipo de Combustível 2 | G6: =$B$801&" 3" -> Tipo de Combustível 3 | H6: =$B$801&" 4" -> Tipo de Combustível 4 | I6: =$B$801&" 5" -> Tipo de Combustível 5 | J6: =$B$801&" 6" -> Tipo de Combustível 6 | M6: =IF(ISERROR('Análise Financeira'!S14+'Análise Financeira'!S22+'Análise Financeira'!S36),3,'Análise Financeira'!S14+'Análise Financeira'!S22+'Análise Financeira'!S36) -> 7460.1915 | N6: 4010004 | AA6: 665 | AB6: 3 | AC6: 664 | AD6: 17 | AE6: TRUE | AF6: EEM-SWH | AG6: FALSE | AP6: 42 | AQ6: 10 | AR6: 42 | AS6: 17 | AT6: 42 | AU6: 9
B7: =$B$801 -> Tipo de Combustível | E7: =$F$1098 -> Eletricidade | N7: 2010106 | AA7: 666 | AB7: 3 | AC7: 665 | AD7: 17 | AE7: TRUE | AF7: EEM-SWH | AG7: FALSE | AP7: 43 | AQ7: 10 | AR7: 43 | AS7: 17 | AT7: 43 | AU7: 9
B8: =Language!C357 -> Consumo de combustível - unitário | E8: =VLOOKUP(E7,LN_FuelList,3,FALSE) -> MWh | F8: =VLOOKUP(F7,LN_FuelList,3,FALSE) -> #N/A | G8: =VLOOKUP(G7,LN_FuelList,3,FALSE) -> #N/A | H8: =VLOOKUP(H7,LN_FuelList,3,FALSE) -> #N/A | I8: =VLOOKUP(I7,LN_FuelList,3,FALSE) -> #N/A | J8: =VLOOKUP(J7,LN_FuelList,3,FALSE) -> #N/A | N8: 111632 | AA8: 827 | AB8: 2 | AC8: 826 | AD8: 17 | AE8: TRUE | AF8: EE_PS | AG8: FALSE | AP8: 44 | AQ8: 10 | AR8: 44 | AS8: 17 | AT8: 44 | AU8: 9
B9: =Language!C359 -> Preço combustível - unidade | E9: =VLOOKUP(E7,LN_FuelList,5,FALSE) -> €/kWh | F9: =VLOOKUP(F7,LN_FuelList,5,FALSE) -> #N/A | G9: =VLOOKUP(G7,LN_FuelList,5,FALSE) -> #N/A | H9: =VLOOKUP(H7,LN_FuelList,5,FALSE) -> #N/A | I9: =VLOOKUP(I7,LN_FuelList,5,FALSE) -> #N/A | J9: =VLOOKUP(J7,LN_FuelList,5,FALSE) -> #N/A | N9: 4010010 | AA9: 827 | AB9: 4 | AC9: 826 | AD9: 18 | AE9: TRUE | AF9: EE_PS | AG9: FALSE | AP9: 45 | AQ9: 10 | AR9: 45 | AS9: 17 | AT9: 45 | AU9: 9
B10: =$B$804 -> Preço do combustível | N10: 4010012 | AA10: 933 | AB10: 3 | AC10: 933 | AD10: 17 | AE10: TRUE | AF10: EEM_UserDef | AG10: FALSE | AP10: 47 | AQ10: 10 | AR10: 47 | AS10: 17 | AT10: 47 | AU10: 9
N11: 4010004 | AA11: 934 | AB11: 3 | AC11: 934 | AD11: 17 | AE11: TRUE | AF11: EEM_UserDef | AG11: FALSE | AP11: 48 | AQ11: 10 | AR11: 48 | AS11: 17 | AT11: 48 | AU11: 9
N12: 4010004 | AA12: 935 | AB12: 3 | AC12: 935 | AD12: 17 | AE12: TRUE | AF12: EEM_UserDef | AG12: FALSE | AP12: 49 | AQ12: 10 | AR12: 49 | AS12: 17 | AT12: 49 | AU12: 9
B13: =Language!C2469 -> Horário | C13: =C221 -> Unidade | E13: =B13&" 1" -> Horário 1 | F13: =B13&" 2" -> Horário 2 | G13: =B13&" 3" -> Horário 3 | H13: =B13&" 4" -> Horário 4 | I13: =B13&" 5" -> Horário 5 | J13: =B13&" 6" -> Horário 6 | N13: 4010014 | AP13: 50 | AQ13: 10 | AR13: 50 | AS13: 17 | AT13: 50 | AU13: 9
B14: =B206 -> Descrição | E14: =Language!C2316 -> 24/7 | N14: 4010016 | AP14: 51 | AQ14: 10 | AR14: 51 | AS14: 17 | AT14: 51 | AU14: 9
F15: =Language!C2445 -> Ocupado | G15: =$F$15 -> Ocupado | H15: =$F$15 -> Ocupado | I15: =$F$15 -> Ocupado | J15: =$F$15 -> Ocupado | N15: 4010014 | AP15: 53 | AQ15: 10 | AR15: 53 | AS15: 17 | AT15: 53 | AU15: 9
B16: =Language!C2019 -> Temperatura - aquecimento ambiental | C16: °C | N16: 4010018 | P16: =IF(OR(C16=$C$1178,C16=""),1,5/9) -> 1 | Q16: =$P16*(E16+40)-40 -> 0 | R16: =$P16*(F16+40)-40 -> 0 | S16: =$P16*(G16+40)-40 -> 0 | T16: =$P16*(H16+40)-40 -> 0 | U16: =$P16*(I16+40)-40 -> 0 | V16: =$P16*(J16+40)-40 -> 0 | AP16: 54 | AQ16: 10 | AR16: 54 | AS16: 17 | AT16: 54 | AU16: 9
B17: =Language!C2018 -> Temperatura - refrigeração ambiental | C17: °C | N17: 4010020 | P17: =IF(OR(C17=$C$1178,C17=""),1,5/9) -> 1 | Q17: =$P17*(E17+40)-40 -> 0 | R17: =$P17*(F17+40)-40 -> 0 | S17: =$P17*(G17+40)-40 -> 0 | T17: =$P17*(H17+40)-40 -> 0 | U17: =$P17*(I17+40)-40 -> 0 | V17: =$P17*(J17+40)-40 -> 0 | AP17: 55 | AQ17: 10 | AR17: 55 | AS17: 17 | AT17: 55 | AU17: 9
F18: =Language!C2507 -> Desocupado | G18: =$F$18 -> Desocupado | H18: =$F$18 -> Desocupado | I18: =$F$18 -> Desocupado | J18: =$F$18 -> Desocupado | N18: 4010014 | AP18: 56 | AQ18: 10 | AR18: 56 | AS18: 17 | AT18: 56 | AU18: 9
B19: =Language!C2020 -> Temperatura - desocupado | C19: +/-°C | N19: 4010022 | P19: =IF(OR(C19=$F$1174,C19=""),1,5/9) -> 1 | R19: =$P19*(F19) -> 0 | S19: =$P19*(G19) -> 0 | T19: =$P19*(H19) -> 0 | U19: =$P19*(I19) -> 0 | V19: =$P19*(J19) -> 0 | AP19: 57 | AQ19: 10 | AR19: 57 | AS19: 17 | AT19: 57 | AU19: 9
F20: =F15 -> Ocupado | G20: =G15 -> Ocupado | H20: =H15 -> Ocupado | I20: =I15 -> Ocupado | J20: =J15 -> Ocupado | N20: 4010014 | AP20: 59 | AQ20: 10 | AR20: 59 | AS20: 17 | AT20: 59 | AU20: 9
B21: =Language!C2444 -> Taxa de ocupação - diária | E21: =Language!C2208 -> h/d | F21: =$E$21 -> h/d | G21: =$E$21 -> h/d | H21: =$E$21 -> h/d | I21: =$E$21 -> h/d | J21: =$E$21 -> h/d | N21: 4010024 | AP21: 60 | AQ21: 10 | AR21: 60 | AS21: 17 | AT21: 60 | AU21: 9
B22: =Language!C2429 -> Segunda Feira | E22: 24 | N22: 4010024 | AP22: 61 | AQ22: 10 | AR22: 61 | AS22: 17 | AT22: 61 | AU22: 9
B23: =Language!C2502 -> Terça feira | E23: 24 | N23: 4010024 | AP23: 62 | AQ23: 10 | AR23: 62 | AS23: 17 | AT23: 62 | AU23: 9
B24: =Language!C2519 -> Quarta feira | E24: 24 | N24: 4010024 | AP24: 63 | AQ24: 10 | AR24: 63 | AS24: 17 | AT24: 63 | AU24: 9
B25: =Language!C2500 -> Quinta feira | E25: 24 | N25: 4010024 | AP25: 65 | AQ25: 10 | AR25: 65 | AS25: 17 | AT25: 65 | AU25: 9
B26: =Language!C2379 -> Sexta feira | E26: 24 | N26: 4010024 | AP26: 66 | AQ26: 10 | AR26: 66 | AS26: 17 | AT26: 66 | AU26: 9
B27: =Language!C2468 -> Sábado | E27: 24 | N27: 4010024 | AP27: 67 | AQ27: 10 | AR27: 67 | AS27: 17 | AT27: 67 | AU27: 9
B28: =Language!C2492 -> Domingo | E28: 24 | N28: 4010024 | AP28: 68 | AQ28: 10 | AR28: 68 | AS28: 17 | AT28: 68 | AU28: 9
B29: =Language!C2443 -> Taxa de ocupação - anual | C29: =Language!C2210 -> h/ano | E29: 8760 | F29: =SUM(F22:F28)*8760/24/7 -> 0 | G29: =SUM(G22:G28)*8760/24/7 -> 0 | H29: =SUM(H22:H28)*8760/24/7 -> 0 | I29: =SUM(I22:I28)*8760/24/7 -> 0 | J29: =SUM(J22:J28)*8760/24/7 -> 0 | N29: 4010026 | AP29: 69 | AQ29: 10 | AR29: 69 | AS29: 17 | AT29: 69 | AU29: 9
C30: =$C$254 -> % | E30: 1 | F30: =F29/8760 -> 0 | G30: =G29/8760 -> 0 | H30: =H29/8760 -> 0 | I30: =I29/8760 -> 0 | J30: =J29/8760 -> 0 | N30: 4010026 | AP30: 71 | AQ30: 10 | AR30: 71 | AS30: 17 | AT30: 71 | AU30: 9
N31: 4010014 | AP31: 72 | AQ31: 10 | AR31: 72 | AS31: 17 | AT31: 72 | AU31: 9
B32: =Language!C1722 -> Temperatura de comutação aquec./ refrigeração | C32: °C | D32: 16 | N32: 4010028 | P32: =IF(OR(C32=$C$1178,C32=""),1,5/9) -> 1 | Q32: =$P32*(D32+40)-40 -> 16 | AP32: 73 | AQ32: 10 | AR32: 73 | AS32: 17 | AT32: 73 | AU32: 9
B33: =Language!C1779 -> Duração da estação de calor | C33: =Language!C2197 -> d | D33: =365-D34 -> 166 | N33: 4010030 | AP33: 74 | AQ33: 10 | AR33: 74 | AS33: 17 | AT33: 74 | AU33: 9
B34: =Language!C1778 -> Duração da estação de frio | C34: =C33 -> d | D34: ='EET2'!D73 -> 199 | N34: 4010032 | S34: =Language!C1688 -> Consumo de combustível - caso de referência | T34: 1 | AP34: 75 | AQ34: 10 | AR34: 75 | AS34: 17 | AT34: 75 | AU34: 9
N35: 4010000 | S35: =Language!C1690 -> Consumo de combustível - caso proposto | T35: 3 | V35: =VLOOKUP(C39,W35:X37,2,FALSE) -> 3.6 | W35: =R182 -> MWh | X35: 1 | AP35: 77 | AQ35: 10 | AR35: 77 | AS35: 17 | AT35: 77 | AU35: 9
M36: =IF(M37=TRUE,90,79) -> 90 | N36: 12000 | S36: =Language!C1693 -> Economia de combustível | T36: 2 | W36: =R184 -> GJ | X36: 3.6 | AP36: 78 | AQ36: 10 | AR36: 78 | AS36: 17 | AT36: 78 | AU36: 9
A37: =Language!C1646 -> Caracarterísticas da instalação | C37: þ | D37: =$G$384 -> Mostrar dado | M37: TRUE | N37: 4020000 | S37: =Language!C2605 -> Demanda de energia - caso de referência | T37: 4 | W37: =Language!C1382 -> milhão Btu | X37: 3.4121416 | AP37: 79 | AQ37: 10 | AR37: 79 | AS37: 17 | AT37: 79 | AU37: 9
B38: =Language!C1969 -> Mostrar: | C38: =C172 -> Aquecimento | D38: =D172 -> Refrigeração | E38: =$F$1098 -> Eletricidade | F38: =$G$244 -> Custo inicial incremental | G38: =Language!C2382 -> Economia - custo de combustível | H38: =Language!C2403 -> Economia de O&M incremental | I38: =B1013 -> Retorno simples | J38: =Language!C1745 -> Inclui a medida ? | M38: =Iniciar!N22 -> 4 | N38: 4020000 | S38: =Language!C2606 -> Demanda de energia - caso proposto | T38: 5 | AP38: 80 | AQ38: 10 | AR38: 80 | AS38: 17 | AT38: 80 | AU38: 9
B39: Economia de combustível | C39: GJ | D39: =$C$39 -> GJ | E39: =$C$39 -> GJ | F39: =Currency -> € | G39: =Currency -> € | H39: =Currency -> € | I39: =C1014 -> ano | J39: ¨ | M39: =EET!BU15 -> 0 | N39: 4020000 | Q39: FALSE | R39: =IF(ISERROR(VLOOKUP(B39,S34:T45,2,FALSE)),4,VLOOKUP(B39,S34:T45,2,FALSE)) -> 2 | S39: =Language!C1635 -> Economia de energia | T39: 6 | AP39: 81 | AQ39: 10 | AR39: 81 | AS39: 17 | AT39: 81 | AU39: 9
B40: =Language!C1283 -> Sistema de Aquecimento | N40: 12100 | Q40: =COUNTIF(Q41:Q148,FALSE) -> 0 | AP40: 83 | AQ40: 10 | AR40: 83 | AS40: 17 | AT40: 83 | AU40: 9
...

Sheet Modelo Energético
A1: =Language!C866&'Análise de Emissões'!B188 -> Modelo Energético RETScreen - Projeto produção de Eletricidade | AO1: 2000000
J2: =Language!C491 -> Mostrar outras unidades | M2: =IF(ISERROR(SUM(M3:N1032)),2,SUM(M3:M1032)+SUM(N3:N1032)*3) -> 27475 | N2: 27475 | O2: HideCodeES | P2: HideCodeES_mem | R2: SI units | S2: SI value | T2: IP units or alternate | U2: IP value or alternate | V2: Additional calculations and conditional formats | AO2: 2000000 | AP2: radiobutton | AQ2: row | AR2: col | AS2: lrow | AT2: lcol | AU2: value | AV2: group | AW2: mLine | AX2: srow | AY2: scol | AZ2: nextRow | BA2: nextCol | BC2: checkbox | BD2: row | BE2: columns | BF2: link row | BG2: link column | BH2: srow | BI2: scolumn
M3: FALSE | O3: Offgrid | P3: =IF(AND(M31=2,EM_gridtype=5),IF(OR(Set_C=1,Set_C>6),5,0),0) -> 0 | Q3: =EM_gridtype -> 1 | X3: =IF(HideCode_projectType3=7,0,IF(AND(HideCode_projectType3=6,HideCodeES_Cool_BL<>1),0,1)) -> 1 | AO3: 2000000 | AQ3: 224 | AR3: 3 | AS3: 226 | AT3: 19 | AU3: TRUE | AV3: EM_Wind | AW3: TRUE | AX3: 224 | AY3: 4 | AZ3: 226 | BA3: 20 | BD3: 228 | BE3: 5 | BF3: 229 | BG3: 13 | BH3: 228 | BI3: 6
A4: =Language!C397 -> Sistema de refrigeração do caso proposto | F4: =Language!C1746 -> Custo inicial incremental | M4: =IF(P4=1,5310,0) -> 0 | O4: level | P4: =Set_Level -> 2 | X4: =IF(HideCode_projectType3=7,0,IF(AND(HideCode_projectType3=6,HideCodeES_Cool_PL<>1),0,100)) -> 100 | AO4: 2010000 | AQ4: 224 | AR4: 3 | AS4: 226 | AT4: 20 | AU4: TRUE | AV4: EM_Wind | AW4: TRUE | AX4: 224 | AY4: 4 | AZ4: 226 | BA4: 21 | BD4: 266 | BE4: 2 | BF4: 266 | BG4: 13 | BH4: 266 | BI4: 3
B5: =Language!C222 -> Carga base do sistema de refrigeração | O5: Internal load | P5: =IF(OR(HideCode_projectType3=2,HideCode_projectType3=10),0,1)+IF(OR(EM_gridtype=1,EM_gridtype=3),0,1) -> 0 | X5: =Language!C131 -> Carga Base do Sistema | AO5: 2010100 | AQ5: 224 | AR5: 3 | AS5: 226 | AT5: 21 | AU5: TRUE | AV5: EM_Wind | AW5: TRUE | AX5: 224 | AY5: 4 | AZ5: 226 | BA5: 19 | BD5: 296 | BE5: 6 | BF5: 296 | BG5: 13 | BH5: 296 | BI5: 7
B6: =Language!C2015 -> Tecnologia | C6: Bomba de calor | K6: =$K$268 -> Mostrar figura | M6: =IF(C6="",1,VLOOKUP(C6,$G$1076:$H$1081,2,FALSE)) -> 1 | O6: HideCodeES_Cool_BL | AO6: 2010102 | AQ6: 313 | AR6: 3 | AS6: 312 | AT6: 13 | AU6: TRUE | AV6: EM_Hydro | AW6: TRUE | AX6: 313 | AY6: 4 | AZ6: 313 | BA6: 13 | BD6: 453 | BE6: 2 | BF6: 453 | BG6: 13 | BH6: 453 | BI6: 3
B7: =Language!C398 -> Fonte de energia | D7: =IF(HideCodeES_Cool_BL=1,K1197,IF(OR(C6=$G$1078,C6=$G$1079),K1198,K1196)) -> Sistema de produção de eletricidade | M7: =IF(D7=K1196,0,1) -> 1 | O7: HideES_Cool_FreeBL | X7: =IF(HideCodeEM_Heat_Peak=0,13,7) -> 13 | AO7: 2010104 | AQ7: 313 | AR7: 3 | AS7: 313 | AT7: 13 | AU7: TRUE | AV7: EM_Hydro | AW7: TRUE | AX7: 313 | AY7: 4 | AZ7: 312 | BA7: 13 | BD7: 967 | BE7: 1 | BF7: 967 | BG7: 16 | BH7: 967 | BI7: 2
B8: =Language!C211 -> Tipo de Combustível | C8: Eletricidade | AO8: 2010106 | AQ8: 446 | AR8: 3 | AS8: 447 | AT8: 13 | AU8: TRUE | AV8: EM-PV | AW8: TRUE | AX8: 446 | AY8: 4 | AZ8: 448 | BA8: 13
B9: =I42 -> Preço do combustível | C9: =VLOOKUP(C8,$B$1176:$F$1289,3,FALSE) -> €/MWh | AO9: 2010108 | AQ9: 446 | AR9: 3 | AS9: 448 | AT9: 13 | AU9: TRUE | AV9: EM-PV | AW9: TRUE | AX9: 446 | AY9: 4 | AZ9: 447 | BA9: 13
B10: =Language!C202 -> Capacidade | C10: kW | E10: =S10/$R$866 -> #DIV/0! | I10: =Language!C61 -> Ver banco de dados de produtos | P10: =IF(CapaUnit_Cooling1=$Z$1086,$Z$1086,$Z$1087) -> kW | R10: kWch | S10: =IF(C10=$Z$1086,D10,IF(C10=$Z$1087,D10/$AA$1087,D10/$AA$1088)) -> 0 | AO10: 2010110
B11: =Language!C1544 -> Coeficiente de desempenho - sazonal | AO11: 2010112
B12: =Language!C1157 -> Fabricante | AO12: 2050012
B13: =Language!C1160 -> Modelo | F13: =Equip_NbUnits & Lang_Unit -> 1 unidade(s) | AO13: 2050014
B14: =Language!C204 -> Frio fornecido | C14: =IF(Unit=TRUE,R14,T14) -> MWh | D14: =IF(Unit=TRUE,S14,U14) -> 0 | E14: =S14/$R$867 -> #DIV/0! | F14: =IF($M$3=FALSE,"",IF(Unit=FALSE,R14,T14)) | G14: =IF($M$3=FALSE,"",IF(Unit=FALSE,S14,U14)) | R14: =Language!C1396 -> MWh | S14: ='Carga e Rede'!AN335 -> 0 | T14: =Z1103 -> TRh | U14: =S14*$AA$1088*1000 -> 0 | AO14: 2010118
B15: =Language!C223 -> Carga de ponta do sistema de refrigeração | C15: =IF(AND(Equip_CoolType2=G1081,S20>0),G1086,IF(S21<S20,Language!C235,IF(S20=0,IF(Equip_CoolType2=G1081,"",G1087),""))) -> Sistema de ponta não requerido | M15: =IF(ISERROR(S20),0,IF(AND(C16=G1081,S20=0),0,100)) -> 100 | O15: HideCodeES_Cool_Peak | AO15: 2010101
B16: =B6 -> Tecnologia | C16: Compressor | M16: =IF(C16="",1,VLOOKUP(C16,$G$1076:$H$1081,2,FALSE)) -> 1 | O16: HideCodeES_Cool_PL | AO16: 2010103
B17: =Language!C398 -> Fonte de energia | C17: =IF(HideCodeES_Cool_PL=1,K1197,IF(OR(C16=$G$1078,C16=$G$1079),K1198,K1196)) -> Sistema de produção de eletricidade | M17: =IF(C17=K1196,0,1) -> 1 | O17: HideES_Cool_FreePL | AO17: 2010104
B18: =B8 -> Tipo de Combustível | C18: Eletricidade | O18: =G1087 -> Sistema de ponta não requerido | AO18: 2010106
B19: =I42 -> Preço do combustível | C19: =VLOOKUP(C18,$B$1176:$F$1289,3,FALSE) -> €/MWh | AO19: 2010108
B20: =Language!C215 -> Capacidade sugerida | C20: =IF(Unit=TRUE,R20,T20) -> kW | D20: =IF(Unit=TRUE,S20,U20) -> 0 | F20: =IF($M$3=FALSE,"",IF(Unit=FALSE,R20,T20)) | G20: =IF($M$3=FALSE,"",IF(Unit=FALSE,S20,U20)) | R20: =Language!C1364 -> kW | S20: =IF(R866-S10<0,0,R866-S10) -> 0 | T20: =Z1099 -> TR | U20: =S20*$AA$1088 -> 0 | AO20: 2010109
B21: =Language!C202 -> Capacidade | C21: kW | E21: =S21/$R$866 -> #DIV/0! | I21: =Language!C61 -> Ver banco de dados de produtos | P21: =IF(CapaUnit_Cooling2=$Z$1086,$Z$1086,$Z$1087) -> kW | R21: kWch | S21: =IF(C21=$Z$1086,D21,IF(C21=$Z$1087,D21/$AA$1087,D21/$AA$1088)) -> 0 | AO21: 2010111
B22: =B11 -> Coeficiente de desempenho - sazonal | AO22: 2010112
B23: =B12 -> Fabricante | AO23: 2050012
B24: =B13 -> Modelo | F24: =$J$1063 & Lang_Unit -> 1 unidade(s) | AO24: 2050014
B25: =B14 -> Frio fornecido | C25: =IF(Unit=TRUE,R25,T25) -> MWh | D25: =IF(Unit=TRUE,S25,U25) -> 0 | E25: =S25/$R$867 -> #DIV/0! | F25: =IF($M$3=FALSE,"",IF(Unit=FALSE,R25,T25)) | G25: =IF($M$3=FALSE,"",IF(Unit=FALSE,S25,U25)) | R25: =$R$14 -> MWh | S25: ='Carga e Rede'!AO335 -> 0 | T25: =T14 -> TRh | U25: =S25*$AA$1088*1000 -> 0 | AO25: 2010118
AO26: 2000000
A27: =Language!C407 -> Sitema de aquecimento do caso proposto | H27: =F4 -> Custo inicial incremental | M27: =HideCode_projectType -> 2 | O27: HideCode_projectType3 | AO27: 2020000
B28: =Language!C408 -> Seleção do Sistema | C28: Carga Base do Sistema | M28: =IF(C28="",1,MATCH(C28,ES_TypeBI,0)) -> 1 | O28: HideCodeES_HSS | AO28: 2020002
A29: =Language!C409 -> Sistema de eletricidade do caso proposto | H29: =F4 -> Custo inicial incremental | M29: =HideCodeEM_1+HideCodeES_PSS*123 -> 21056 | O29: Min Cap | P29: =IF(OR(EM_gridtype=1,EM_gridtype=3),100,0)+M31 -> 102 | AO29: 2030000
B30: =Language!C408 -> Seleção do Sistema | C30: Carga Base do Sistema | M30: =IF(C30=G1074,2,1) -> 1 | O30: HideCodeES_PSS | AO30: 2030002
B31: =IF(M31=2,"",IF(M31=10,IF(C854=E1094,Language!C199,Language!C209),(IF(OR(HideCode_projectType3=1,HideCode_projectType3=6),Language!C218,IF(C30=G1073,Language!C199,IF(C854=E1094,Language!C199,Language!C209)))))) | M31: =Iniciar!P20 -> 2 | AO31: 2020004
B32: =B6 -> Tecnologia | C32: Sistema à biomassa | M32: =IF(C32="",1,IF(ISERROR(MATCH(C32,E1079:E1084,0)),1,MATCH(C32,E1079:E1084,0))) -> 1 | O32: HideCodeES_HeatST1 | AO32: 2020104
B33: =Language!C2015 -> Tecnologia | C33: Fotovoltaica | M33: =IF(OR(Equip_PowerType="",Equip_PowerType=Iniciar!D121),1,MATCH(Equip_PowerType,ES_PowerType,0)) -> 9 | O33: HideCodeES_PowerST1 | AO33: 2030008
B34: =B33 -> Tecnologia | C34: =Equip_PowerType -> Fotovoltaica | M34: =HideCodeES_PowerST1*123 -> 1107 | AO34: 2030008
B35: =Language!C410 -> Disponibilidade | C35: % | F35: =IF(C35=$Z$1105,FIXED(U35*100,1)&T35,FIXED(S35,0)&" "&R35) -> 8 760 h | R35: =Language!C1339 -> h | S35: =IF(OR(M33=7,M33=8,M33=9,M33>10),8760,IF(C35=Z1105,D35,E35*8760)) -> 8760 | T35: =Language!C1306 -> % | U35: =S35/8760 -> 1 | AO35: 2030010
AO36: 2030100
B37: =Language!C411 -> Método-seleção de combustível | C37: Combustível único | K37: =IF(Ferramentas!E411<1,G1097,"") | M37: =IF(C37="",1,MATCH(C37,ES_FuelMethod,0)) -> 1 | O37: HideCodeES_Fuel1 | AO37: 2030100
B38: =B8 -> Tipo de Combustível | C38: Gas natural - m³ | K38: =Language!C62 -> Completar planilha Ferramentas | M38: =M37*100 -> 100 | R38: MJ/kg | S38: =VLOOKUP(C38,$B$1176:$F$1289,4,FALSE) -> 47.856 | T38: Btu/lb | U38: =S38*$AA$1092 -> 20574.377 | V38: =SUMIF($B$1102:$B$1105,C38,$A$1102:$A$1105) -> 0 | X38: Conditional format | AO38: 2010106
B39: =I42 -> Preço do combustível | C39: =VLOOKUP(C38,$B$1176:$F$1289,3,FALSE) -> €/m³ | R39: $/MWh | S39: =1000/S38/VLOOKUP(C38,$B$1176:$F$1289,5,FALSE)*D39*3.6 -> 0 | AO39: 2010108
AO40: 2030008
...

Sheet Análise de Custos
A1: =Language!C869&'Análise de Emissões'!B188 -> Análise de Custos RETScreen - Projeto produção de Eletricidade | U1: 60000
O2: =IF(ISERROR(SUM(O3:P256)),3,1+SUM(O3:P256)) -> 21329 | P2: 21329 | U2: 60000 | V2: Currency Range
O3: =IF(R5=TRUE,IF(G6="",2,MATCH(G6,D266:D267,0)),100) -> 1 | U3: 60000 | V3: Name | W3: Sign
A4: =Language!C494 -> Opções | O4: =Iniciar!O28 -> 20912 | Q4: Left buttons | R4: Right buttons | U4: 60100 | V4: $ | W4: $
C5: =Language!C1811 -> Método 1 | D5: =Language!C48 -> Notas/faixa | H5: =Language!C496 -> Segunda moeda | I5: $ | O5: =IF(Currency2_name="",1,MATCH(Currency2_name,currency_list,0)) -> 1 | Q5: FALSE | R5: TRUE | S5: 60106 | T5: 60108 | U5: 60100 | V5: Euro | W5: €
C6: =Language!C1812 -> Método 2 | D6: =Language!C496 -> Segunda moeda | F6: =D5 -> Notas/faixa | G6: Nenhum | I6: =Language!C497 -> Símbolo | M6: =D267 -> Definido pelo usuário | O6: =IF(Q6=TRUE,13,5)+IF(R5=TRUE,7,11)+IF(R7=TRUE,22,45) -> 65 | Q6: TRUE | R6: FALSE | S6: 60106 | T6: 60110 | U6: 60100 | V6: £ | W6: £
D7: =Language!C1568 -> Alocação de custo | I7: =Language!C498&Currency&"/"&Currency2 -> Preço: €/$ | J7: 1 | O7: =HideCodeCA_ProjectT*123 -> 0 | Q7: FALSE | R7: FALSE | S7: 60106 | T7: 60112 | U7: 60100 | V7: ¥ | W7: ¥
O8: =IF($Q$6=FALSE,IF(Q5=TRUE,2,1),0) -> 0 | Q8: Multiplicative currency rate | U8: 60000 | V8: Y | W8: Y
A9: =Language!C500 -> Custos iniciais (créditos) | D9: =Language!C180 -> Unidade | E9: =Language!C501 -> Quantidade | F9: =Language!C502 -> Custo unitário | G9: =Language!C226 -> Quantidade | H9: =Language!C503 -> Custos relativos | I9: =$D$192 -> % | J9: =G9 -> Quantidade | M9: =D5 -> Notas/faixa | O9: =HideCode_projectType*100 -> 200 | Q9: =IF(R7=TRUE,1,J7) -> 1 | U9: 61000 | V9: Rs | W9: Rs
B10: =Language!C683 -> Custos iniciais | U10: 60000 | V10: Definido pelo usuário
C11: =Language!C1284 -> Sistema de produção de eletricidade | D11: =D61 -> kW | E11: ='Modelo Energético'!V870 -> 3.795 | G11: =E11*F11*O11 -> 0 | O11: =IF(OR(HideCode_projectType=1,HideCode_projectType=3,HideCode_projectType=6,HideCode_projectType>7),0,1) -> 1 | U11: 60000 | V11: Nenhum | W11: -
C12: =Language!C1283 -> Sistema de Aquecimento | D12: =IF(Set_OpenClose=10702,'Modelo Energético '!C649,D74) -> kW | E12: ='Modelo Energético'!S895 -> 0 | G12: =E12*F12*O12 -> 0 | O12: =IF(OR(HideCode_projectType=2,HideCode_projectType=3,HideCode_projectType=5,HideCode_projectType>7),0,1)*(1-O13) -> 0 | U12: 60000 | V12: Afganistão | W12: AFA
C13: =C12 -> Sistema de Aquecimento | G13: =G73 -> 0 | O13: =IF(HideCodeCA_SWH=1,1,0) -> 0 | U13: 60000 | V13: África do Sul | W13: ZAR
C14: =Language!C542 -> Sistema de refrigeração | D14: =D87 -> kW | E14: ='Modelo Energético'!S927 -> 0 | G14: =E14*F14*O14 -> 0 | O14: =IF(OR(HideCode_projectType=1,HideCode_projectType=2,HideCode_projectType=4,HideCode_projectType>7),0,1) -> 0 | U14: 60000 | V14: Albania | W14: ALL
C15: =Language!C1746 -> Custo inicial incremental | G15: ='Modelo Energético '!G1091 -> 0 | O15: =IF(G15=0,0,1) -> 0 | U15: 60000 | V15: Alemanha | W15: EUR
G16: =IF(D16=$C$261,-1,1)*E16*F16 -> 0 | U16: 60000 | V16: Andorra | W16: EUR
C17: =B97 -> Ações de Eficiência energética | D17: custo | G17: =IF(D17=$C$261,-1,1)*E17*F17 -> 0 | U17: 60000 | V17: Angola | W17: AOA
C18: =C196 -> Contingências | D18: =$D$192 -> % | F18: =SUM(G11:G17) -> 0 | G18: =E18*F18 -> 0 | U18: 60000 | V18: Anguila | W18: XCD
C19: =C197 -> Juros durante a construçaõ | F19: =F18+G18 -> 0 | G19: =F19*D19*E19/12/2 -> 0 | U19: 60000 | V19: Antigua e Barbuda | W19: XCD
A20: =A199 -> Total de custos de investimento | U20: 60000 | V20: Antilhas Holandesas | W20: ANG
U21: 60000 | V21: Arábia Saudita | W21: SAR
B22: =Language!C508 -> Estudo de viabilidade | U22: 61100 | V22: Argélia | W22: DZD
C23: =Language!C509 -> Pesquisa de campo | D23: =Language!C1397 -> d-p | G23: =E23*F23 -> 0 | J23: =G23/$Q$9*I23 -> 0 | O23: =IF(Currency_name="",1,MATCH(Currency_name,currency_list,0)) -> 2 | U23: 61102 | V23: Argentina | W23: ARS
C24: =Language!C510 -> Avaliação de recursos | D24: =$D$28 -> projeto | G24: =E24*F24 -> 0 | J24: =G24/$Q$9*I24 -> 0 | U24: 61118 | V24: Armenia | W24: AMD
C25: =Language!C511 -> Avaliação Ambiental | D25: =$D$23 -> d-p | G25: =E25*F25 -> 0 | J25: =G25/$Q$9*I25 -> 0 | U25: 61128 | V25: Aruba | W25: AWG
C26: =Language!C512 -> Projeto preliminar | D26: =$D$23 -> d-p | G26: =E26*F26 -> 0 | J26: =G26/$Q$9*I26 -> 0 | U26: 61130 | V26: Austrália | W26: AUD
C27: =Language!C513 -> Estimativa detalhada de custos | D27: =$D$23 -> d-p | G27: =E27*F27 -> 0 | J27: =G27/$Q$9*I27 -> 0 | U27: 61132 | V27: Áustria | W27: EUR
C28: =Language!C514 -> Estudo da linha de base e PS dos GEE | D28: =Language!C1399 -> projeto | G28: =E28*F28 -> 0 | J28: =G28/$Q$9*I28 -> 0 | U28: 61134 | V28: Azerbaijão | W28: AZM
C29: =Language!C515 -> Preparação de relatório | D29: =$D$23 -> d-p | G29: =E29*F29 -> 0 | J29: =G29/$Q$9*I29 -> 0 | U29: 61136 | V29: Bahamas | W29: BSD
C30: =Language!C516 -> Gestão do Projeto | D30: =$D$23 -> d-p | G30: =E30*F30 -> 0 | J30: =G30/$Q$9*I30 -> 0 | U30: 61138 | V30: Bahrain | W30: BHD
C31: =Language!C517 -> Viagem & Acomodação | D31: =Language!C1402 -> p-viagem | G31: =E31*F31 -> 0 | J31: =G31/$Q$9*I31 -> 0 | U31: 61140 | V31: Bangladesh | W31: BDT
C32: =F273 -> Definido pelo usuário | D32: custo | G32: =IF(D32=$C$261,-1,1)*E32*F32 -> 0 | J32: =G32/$Q$9*I32 -> 0 | U32: 61142 | V32: Barbados | W32: BBD
G33: =IF(D33=$C$261,-1,1)*E33*F33 -> 0 | J33: =G33/$Q$9*I33 -> 0 | U33: 61142 | V33: Bélgica | W33: EUR
C34: =B22 -> Estudo de viabilidade | D34: custo | G34: =IF(D34=$C$261,-1,1)*E34*F34 -> 0 | J34: =G34/$Q$9*I34 -> 0 | U34: 61100 | V34: Belize | W34: BZD
C35: =Language!C518 -> Subtotal | G35: =IF($Q$6<>TRUE,SUM(G23:G33),G34) -> 0 | H35: =IF(G199=0,"",G35/$G$199) -> 0 | I35: =IF(J35=0,0,J35*$Q$9/G35) -> 0 | J35: =IF($Q$6<>TRUE,SUM(J23:J33),J34) -> 0 | U35: 61100 | V35: Benin | W35: XOF
B36: =Language!C519 -> Desenvolvimento | U36: 61200 | V36: Bermuda | W36: BMD
C37: =Language!C520 -> Negociação do contrato | D37: =$D$23 -> d-p | G37: =E37*F37 -> 0 | J37: =G37/$Q$9*I37 -> 0 | U37: 61202 | V37: Bielorussia | W37: BYR
C38: =Language!C521 -> Licenças e aprovações | D38: =$D$23 -> d-p | G38: =E38*F38 -> 0 | J38: =G38/$Q$9*I38 -> 0 | U38: 61204 | V38: Bolívia | W38: BOB
C39: =Language!C522 -> Visita de campo e registros | D39: =$D$23 -> d-p | G39: =E39*F39 -> 0 | J39: =G39/$Q$9*I39 -> 0 | U39: 61206 | V39: Bosnia-Herzegovina | W39: BAM
C40: =Language!C523 -> Validação e Registro do GEE | D40: =$D$28 -> projeto | G40: =E40*F40 -> 0 | J40: =G40/$Q$9*I40 -> 0 | U40: 61208 | V40: Botswana | W40: BWP
...

Sheet Análise de Emissões
A1: =Language!C870&B188 -> Análise da Redução das Emissões RETScreen - Projeto produção de Eletricidade | N1: =IF(ISERROR(SUM(N2:N13, N40:N195)+GHG_Type),4,SUM(N2:N13, N40:N195)+GHG_Type) -> 3372.8104 | O1: 3372.8104 | P1: TRUE | Q1: GHG | R1: TRUE | S1: Simplified | AB1: 90000 | AC1: radiobuttons | AD1: row | AE1: col | AF1: lrow | AG1: lcol | AH1: value | AI1: group | AK1: checbox | AL1: row | AM1: columns | AN1: link row | AO1: link column | AP1: srow | AQ1: scolumn
P2: TRUE | Q2: CDM | R2: FALSE | S2: Standard | U2: 25 | V2: =Language!$C$587 -> tons CO2 = | W2: =Language!C588 -> 1 ton CH4 | AB2: 90000 | AD2: 5 | AE2: 1 | AF2: 1 | AG2: 18 | AH2: TRUE | AI2: GHG Analysis | AL2: 45 | AM2: 2 | AN2: 45 | AO2: 16 | AP2: 45 | AQ2: 5
C3: =Language!C24 -> Análise de Emissões | P3: FALSE | Q3: Baseline | R3: FALSE | S3: Custom | U3: 298 | V3: =Language!$C$587 -> tons CO2 = | W3: =Language!C589 -> 1 ton N2O | AB3: 91002 | AD3: 6 | AE3: 1 | AF3: 2 | AG3: 18 | AH3: TRUE | AI3: GHG Analysis
S4: EM off-grid | T4: =Iniciar!P3 -> 0 | V4: Project capacity | W4: =IF(OR(R5=2,R5=4,R5=5,R5=7),SUM('Modelo Energético'!H940:H946)-IF('Modelo Energético'!D946='Modelo Energético'!P1066,'Modelo Energético'!H946,0),0)/1000 -> 0.003795 | X4: MW | AB4: 91002 | AD4: 7 | AE4: 1 | AF4: 3 | AG4: 18 | AH4: TRUE | AI4: GHG Analysis
A5: ¤ | C5: =Language!C1811 -> Método 1 | H5: =Language!C585 -> Potencial de Aquecimento global dos GEE | N5: =IF(Link_GHG_Start=TRUE,100+GHG_Type*13,0)+IF(OR(R5=1,R5=3,R5=6),0,1)*IF(EM_gridtype=5,100,0) -> 139 | O5: =IF(Set_Level=1,3,IF(R2=TRUE,1,IF(R3=TRUE,2,3))) -> 3 | P5: =H6 -> 25 | Q5: GHG_POT_mem | R5: =HideCode_projectType -> 2 | S5: Project type | T5: =EM_gridtype -> 1 | U5: EM_gridtype | V5: Energy savings | W5: =(Q64-Q130)/3600 -> 0 | X5: GWh | AB5: 91002
A6: ¡ | C6: =Language!C1812 -> Método 2 | H6: 25 | I6: =IF(GHG_Type=1,Q7,Language!$C$587) -> tons CO2 = | J6: =Language!C588 -> 1 ton CH4 | K6: (IPCC 2007) | N6: =LangIndex -> 23 | P6: =H7 -> 298 | R6: ='Carga e Rede'!M377+'Modelo Energético'!G1179+Q63+IF(AND(R5=2,T5<>5),1,0) -> 20.405197 | S6: if greater than 0 electricity used | AB6: 91002
A7: ¡ | C7: =Language!C1813 -> Método 3 | H7: 298 | I7: =IF(GHG_Type=1,Q8,Language!$C$587) -> tons CO2 = | J7: =Language!C589 -> 1 ton N2O | K7: (IPCC 2007) | P7: 25 | Q7: =U2&" "&Language!$C$587 -> 25 tons CO2 = | R7: =IF(OR(R5=1,R5=3,R5=6),0,100)*0 -> 0 | AB7: 91002
P8: 298 | Q8: =U3&" "&Language!$C$587 -> 298 tons CO2 = | AB8: 91002
AB9: 90000
A10: =Language!C590 -> Sistema elétrico de referência ( Baseline) | N10: =IF(ISERROR(R6),100,IF(R6+R7>0,100,0)) -> 100 | AB10: 92000
AB11: 92000
D12: =Language!C412 -> Mix do combustível | E12: =Language!C591 -> Fator de emissão de CO2 | F12: =Language!C592 -> Fator de emissão de CH4 | G12: =Language!C593 -> Fator de emissão de N2O | H12: =Language!C594 -> Eficiência na geração de eletricidade | J12: =Language!C595 -> Perdas T&D | K12: =Language!C596 -> Fator de emissão de GEE | AB12: 92000
C13: =Language!C211 -> Tipo de Combustível | D13: =Language!C1306 -> % | E13: =Language!C1354 -> kg/GJ | F13: =$E$13 -> kg/GJ | G13: =$E$13 -> kg/GJ | H13: =D13 -> % | J13: =D13 -> % | K13: tCO2/MWh | AB13: 92000
C14: ='Carga e Rede'!P367 -> Gás Natural | D14: 1 | H14: =H26 -> 0 | K14: =IF(OR(HideCode_projectType=1,HideCode_projectType=3,HideCode_projectType=6,EM_gridtype<5),0,IF(D14=0,0,(E14+(F14*$P$5)+(G14*$P$6))*(1/H26)*(1/(1-J14))*3.6*(1/1000))) -> 0 | S14: =IF(OR(H14=0,H14=""),1,H14) -> 1 | T14: =IF(OR(J14=0,J14=""),0,J14) -> 0 | AB14: 92000
B15: Gás Natural | E15: 49.36 | F15: 0.0036253859 | G15: 0.00090634647 | H15: 0.40785591 | K15: =IF(OR(B15="",D15=0),0,(E15+(F15*$P$5)+(G15*$P$6))*(1/H15)*(1/(1-J15))*3.6*(1/1000)) -> 0 | N15: =SUM(N16:N36) -> 16 | O15: 16 | S15: =IF(OR(H15=0,H15=""),1,H15) -> 0.40785591 | T15: =IF(OR(J15=0,J15=""),0,J15) -> 0 | AB15: 92000
K16: =IF(OR(B16="",D16=0),0,(E16+(F16*$P$5)+(G16*$P$6))*(1/H16)*(1/(1-J16))*3.6*(1/1000)) -> 0 | N16: =IF(AND(B15="",B16="",D16=""),1,0) -> 0 | S16: =IF(OR(H16=0,H16=""),1,H16) -> 1 | T16: =IF(OR(J16=0,J16=""),0,J16) -> 0 | W16: GHG reductions | X16: =F189 -> 0 | Y16: tCO2 | AB16: 92000
K17: =IF(OR(B17="",D17=0),0,(E17+(F17*$P$5)+(G17*$P$6))*(1/H17)*(1/(1-J17))*3.6*(1/1000)) -> 0 | N17: =IF(AND(B16="",B17="",D17=""),1,0) -> 1 | S17: =IF(OR(H17=0,H17=""),1,H17) -> 1 | T17: =IF(OR(J17=0,J17=""),0,J17) -> 0 | W17: Simplified project if =2 | X17: =IF(OR(W4>15,W5>15,X16>15000),1,2) -> 2 | AB17: 92000
K18: =IF(OR(B18="",D18=0),0,(E18+(F18*$P$5)+(G18*$P$6))*(1/H18)*(1/(1-J18))*3.6*(1/1000)) -> 0 | N18: =IF(AND(B17="",B18="",D18=""),1,0) -> 1 | S18: =IF(OR(H18=0,H18=""),1,H18) -> 1 | T18: =IF(OR(J18=0,J18=""),0,J18) -> 0 | W18: CDM project Yes =1 | X18: =IF(P2=TRUE,1,0) -> 1 | AB18: 92000
K19: =IF(OR(B19="",D19=0),0,(E19+(F19*$P$5)+(G19*$P$6))*(1/H19)*(1/(1-J19))*3.6*(1/1000)) -> 0 | N19: =IF(AND(B18="",B19="",D19=""),1,0) -> 1 | S19: =IF(OR(H19=0,H19=""),1,H19) -> 1 | T19: =IF(OR(J19=0,J19=""),0,J19) -> 0 | AB19: 92000
K20: =IF(OR(B20="",D20=0),0,(E20+(F20*$P$5)+(G20*$P$6))*(1/H20)*(1/(1-J20))*3.6*(1/1000)) -> 0 | N20: =IF(AND(B19="",B20="",D20=""),1,0) -> 1 | S20: =IF(OR(H20=0,H20=""),1,H20) -> 1 | T20: =IF(OR(J20=0,J20=""),0,J20) -> 0 | AB20: 92000
K21: =IF(OR(B21="",D21=0),0,(E21+(F21*$P$5)+(G21*$P$6))*(1/H21)*(1/(1-J21))*3.6*(1/1000)) -> 0 | N21: =IF(AND(B20="",B21="",D21=""),1,0) -> 1 | S21: =IF(OR(H21=0,H21=""),1,H21) -> 1 | T21: =IF(OR(J21=0,J21=""),0,J21) -> 0 | AB21: 92000
K22: =IF(OR(B22="",D22=0),0,(E22+(F22*$P$5)+(G22*$P$6))*(1/H22)*(1/(1-J22))*3.6*(1/1000)) -> 0 | N22: =IF(AND(B21="",B22="",D22=""),1,0) -> 1 | S22: =IF(OR(H22=0,H22=""),1,H22) -> 1 | T22: =IF(OR(J22=0,J22=""),0,J22) -> 0 | AB22: 92000
K23: =IF(OR(B23="",D23=0),0,(E23+(F23*$P$5)+(G23*$P$6))*(1/H23)*(1/(1-J23))*3.6*(1/1000)) -> 0 | N23: =IF(AND(B22="",B23="",D23=""),1,0) -> 1 | S23: =IF(OR(H23=0,H23=""),1,H23) -> 1 | T23: =IF(OR(J23=0,J23=""),0,J23) -> 0 | AB23: 92000
K24: =IF(OR(B24="",D24=0),0,(E24+(F24*$P$5)+(G24*$P$6))*(1/H24)*(1/(1-J24))*3.6*(1/1000)) -> 0 | N24: =IF(AND(B23="",B24="",D24=""),1,0) -> 1 | S24: =IF(OR(H24=0,H24=""),1,H24) -> 1 | T24: =IF(OR(J24=0,J24=""),0,J24) -> 0 | V24: Unit switch | AB24: 92000
C25: =Language!C598 -> Mix de Eletricidade | D25: =IF(AND(EM_gridtype=5,GHG_EnergyModelUse=0),D14,SUM(D15:D24)) -> 0 | E25: =IF(AND(EM_gridtype=5,GHG_EnergyModelUse=0),$D$14*E14/$S$14/(1-$T$14),SUMPRODUCT($D$15:$D$24*E15:E24/$S$15:$S$24/(1-$T$15:$T$24))) -> 0 | F25: =IF(AND(EM_gridtype=5,GHG_EnergyModelUse=0),$D$14*F14/$S$14/(1-$T$14),SUMPRODUCT($D$15:$D$24*F15:F24/$S$15:$S$24/(1-$T$15:$T$24))) -> 0 | G25: =IF(AND(EM_gridtype=5,GHG_EnergyModelUse=0),$D$14*G14/$S$14/(1-$T$14),SUMPRODUCT($D$15:$D$24*G15:G24/$S$15:$S$24/(1-$T$15:$T$24))) -> 0 | J25: =IF(AND(EM_gridtype=5,GHG_EnergyModelUse=0),J14,SUMPRODUCT(D15:D24,J15:J24)) -> 0 | K25: =IF(AND(EM_gridtype=5,GHG_EnergyModelUse=0),K14,SUMPRODUCT(D15:D24,K15:K24)) -> 0 | S25: =IF(GHG_Type=2,E25,E37) -> 0 | T25: =IF(GHG_Type=2,F25,F37) -> 0 | U25: =IF(GHG_Type=2,G25,G37) -> 0 | AB25: 92000
C26: =C14 -> Gás Natural | D26: =D14 -> 1 | E26: =IF(C26="","",VLOOKUP($C26,$C$207:$F$221,2,FALSE)) -> 54.46 | F26: =IF($C26="","",VLOOKUP($C26,$C$207:$F$221,3,FALSE)) -> 0.004 | G26: =IF($C26="","",VLOOKUP($C26,$C$207:$F$221,4,FALSE)) -> 0.001 | H26: =IF('Carga e Rede'!W222=0,0,'Carga e Rede'!D246*3.6/'Carga e Rede'!W222) -> 0 | K26: =IF(OR(HideCode_projectType=1,HideCode_projectType=3,HideCode_projectType=6,EM_gridtype<5),0,IF(D26=0,0,(E26+(F26*U$2)+(G26*U$3))*(1/H26)*(1/(1-J26))*3.6*(1/1000))) -> 0 | P26: =IF(E26="",0,E26) -> 54.46 | Q26: =IF(F26="",0,F26) -> 0.004 | R26: =IF(G26="",0,G26) -> 0.001 | S26: =IF(OR(H26=0,H26=""),1,H26) -> 1 | T26: =IF(OR(J26=0,J26=""),0,J26) -> 0 | AB26: 92000
B27: Gás Natural | E27: =IF(B27="","",VLOOKUP($B27,$C$207:$F$221,2,FALSE)) -> 54.46 | F27: =IF($B27="","",VLOOKUP($B27,$C$207:$F$221,3,FALSE)) -> 0.004 | G27: =IF($B27="","",VLOOKUP($B27,$C$207:$F$221,4,FALSE)) -> 0.001 | H27: 0.40785591 | K27: =IF(OR(B27="",D27=0),0,(E27+(F27*U$2)+(G27*U$3))*(1/H27)*(1/(1-J27))*3.6*(1/1000)) -> 0 | P27: =IF(E27="",0,E27) -> 54.46 | Q27: =IF(F27="",0,F27) -> 0.004 | R27: =IF(G27="",0,G27) -> 0.001 | S27: =IF(OR(H27=0,H27=""),1,H27) -> 0.40785591 | T27: =IF(OR(J27=0,J27=""),0,J27) -> 0 | AB27: 92000
E28: =IF(B28="","",VLOOKUP($B28,$C$207:$F$221,2,FALSE)) | F28: =IF($B28="","",VLOOKUP($B28,$C$207:$F$221,3,FALSE)) | G28: =IF($B28="","",VLOOKUP($B28,$C$207:$F$221,4,FALSE)) | K28: =IF(OR(B28="",D28=0),0,(E28+(F28*U$2)+(G28*U$3))*(1/H28)*(1/(1-J28))*3.6*(1/1000)) -> 0 | N28: =IF(AND(B27="",B28="",D28=""),1,0) -> 0 | P28: =IF(E28="",0,E28) -> 0 | Q28: =IF(F28="",0,F28) -> 0 | R28: =IF(G28="",0,G28) -> 0 | S28: =IF(OR(H28=0,H28=""),1,H28) -> 1 | T28: =IF(OR(J28=0,J28=""),0,J28) -> 0 | AB28: 92000
E29: =IF(B29="","",VLOOKUP($B29,$C$207:$F$221,2,FALSE)) | F29: =IF($B29="","",VLOOKUP($B29,$C$207:$F$221,3,FALSE)) | G29: =IF($B29="","",VLOOKUP($B29,$C$207:$F$221,4,FALSE)) | K29: =IF(OR(B29="",D29=0),0,(E29+(F29*U$2)+(G29*U$3))*(1/H29)*(1/(1-J29))*3.6*(1/1000)) -> 0 | N29: =IF(AND(B28="",B29="",D29=""),1,0) -> 1 | P29: =IF(E29="",0,E29) -> 0 | Q29: =IF(F29="",0,F29) -> 0 | R29: =IF(G29="",0,G29) -> 0 | S29: =IF(OR(H29=0,H29=""),1,H29) -> 1 | T29: =IF(OR(J29=0,J29=""),0,J29) -> 0 | AB29: 92000
E30: =IF(B30="","",VLOOKUP($B30,$C$207:$F$221,2,FALSE)) | F30: =IF($B30="","",VLOOKUP($B30,$C$207:$F$221,3,FALSE)) | G30: =IF($B30="","",VLOOKUP($B30,$C$207:$F$221,4,FALSE)) | K30: =IF(OR(B30="",D30=0),0,(E30+(F30*U$2)+(G30*U$3))*(1/H30)*(1/(1-J30))*3.6*(1/1000)) -> 0 | N30: =IF(AND(B29="",B30="",D30=""),1,0) -> 1 | P30: =IF(E30="",0,E30) -> 0 | Q30: =IF(F30="",0,F30) -> 0 | R30: =IF(G30="",0,G30) -> 0 | S30: =IF(OR(H30=0,H30=""),1,H30) -> 1 | T30: =IF(OR(J30=0,J30=""),0,J30) -> 0 | AB30: 92000
E31: =IF(B31="","",VLOOKUP($B31,$C$207:$F$221,2,FALSE)) | F31: =IF($B31="","",VLOOKUP($B31,$C$207:$F$221,3,FALSE)) | G31: =IF($B31="","",VLOOKUP($B31,$C$207:$F$221,4,FALSE)) | K31: =IF(OR(B31="",D31=0),0,(E31+(F31*U$2)+(G31*U$3))*(1/H31)*(1/(1-J31))*3.6*(1/1000)) -> 0 | N31: =IF(AND(B30="",B31="",D31=""),1,0) -> 1 | P31: =IF(E31="",0,E31) -> 0 | Q31: =IF(F31="",0,F31) -> 0 | R31: =IF(G31="",0,G31) -> 0 | S31: =IF(OR(H31=0,H31=""),1,H31) -> 1 | T31: =IF(OR(J31=0,J31=""),0,J31) -> 0 | V31: GJ | AB31: 92000
E32: =IF(B32="","",VLOOKUP($B32,$C$207:$F$221,2,FALSE)) | F32: =IF($B32="","",VLOOKUP($B32,$C$207:$F$221,3,FALSE)) | G32: =IF($B32="","",VLOOKUP($B32,$C$207:$F$221,4,FALSE)) | K32: =IF(OR(B32="",D32=0),0,(E32+(F32*U$2)+(G32*U$3))*(1/H32)*(1/(1-J32))*3.6*(1/1000)) -> 0 | N32: =IF(AND(B31="",B32="",D32=""),1,0) -> 1 | P32: =IF(E32="",0,E32) -> 0 | Q32: =IF(F32="",0,F32) -> 0 | R32: =IF(G32="",0,G32) -> 0 | S32: =IF(OR(H32=0,H32=""),1,H32) -> 1 | T32: =IF(OR(J32=0,J32=""),0,J32) -> 0 | AB32: 92000
E33: =IF(B33="","",VLOOKUP($B33,$C$207:$F$221,2,FALSE)) | F33: =IF($B33="","",VLOOKUP($B33,$C$207:$F$221,3,FALSE)) | G33: =IF($B33="","",VLOOKUP($B33,$C$207:$F$221,4,FALSE)) | K33: =IF(OR(B33="",D33=0),0,(E33+(F33*U$2)+(G33*U$3))*(1/H33)*(1/(1-J33))*3.6*(1/1000)) -> 0 | N33: =IF(AND(B32="",B33="",D33=""),1,0) -> 1 | P33: =IF(E33="",0,E33) -> 0 | Q33: =IF(F33="",0,F33) -> 0 | R33: =IF(G33="",0,G33) -> 0 | S33: =IF(OR(H33=0,H33=""),1,H33) -> 1 | T33: =IF(OR(J33=0,J33=""),0,J33) -> 0 | AB33: 92000
E34: =IF(B34="","",VLOOKUP($B34,$C$207:$F$221,2,FALSE)) | F34: =IF($B34="","",VLOOKUP($B34,$C$207:$F$221,3,FALSE)) | G34: =IF($B34="","",VLOOKUP($B34,$C$207:$F$221,4,FALSE)) | K34: =IF(OR(B34="",D34=0),0,(E34+(F34*U$2)+(G34*U$3))*(1/H34)*(1/(1-J34))*3.6*(1/1000)) -> 0 | N34: =IF(AND(B33="",B34="",D34=""),1,0) -> 1 | P34: =IF(E34="",0,E34) -> 0 | Q34: =IF(F34="",0,F34) -> 0 | R34: =IF(G34="",0,G34) -> 0 | S34: =IF(OR(H34=0,H34=""),1,H34) -> 1 | T34: =IF(OR(J34=0,J34=""),0,J34) -> 0 | AB34: 92000
E35: =IF(B35="","",VLOOKUP($B35,$C$207:$F$221,2,FALSE)) | F35: =IF($B35="","",VLOOKUP($B35,$C$207:$F$221,3,FALSE)) | G35: =IF($B35="","",VLOOKUP($B35,$C$207:$F$221,4,FALSE)) | K35: =IF(OR(B35="",D35=0),0,(E35+(F35*U$2)+(G35*U$3))*(1/H35)*(1/(1-J35))*3.6*(1/1000)) -> 0 | N35: =IF(AND(B34="",B35="",D35=""),1,0) -> 1 | P35: =IF(E35="",0,E35) -> 0 | Q35: =IF(F35="",0,F35) -> 0 | R35: =IF(G35="",0,G35) -> 0 | S35: =IF(OR(H35=0,H35=""),1,H35) -> 1 | T35: =IF(OR(J35=0,J35=""),0,J35) -> 0 | AB35: 92000
E36: =IF(B36="","",VLOOKUP($B36,$C$207:$F$221,2,FALSE)) | F36: =IF($B36="","",VLOOKUP($B36,$C$207:$F$221,3,FALSE)) | G36: =IF($B36="","",VLOOKUP($B36,$C$207:$F$221,4,FALSE)) | K36: =IF(OR(B36="",D36=0),0,(E36+(F36*U$2)+(G36*U$3))*(1/H36)*(1/(1-J36))*3.6*(1/1000)) -> 0 | N36: =IF(AND(B35="",B36="",D36=""),1,0) -> 1 | P36: =IF(E36="",0,E36) -> 0 | Q36: =IF(F36="",0,F36) -> 0 | R36: =IF(G36="",0,G36) -> 0 | S36: =IF(OR(H36=0,H36=""),1,H36) -> 1 | T36: =IF(OR(J36=0,J36=""),0,J36) -> 0 | AB36: 92000
C37: =Language!C598 -> Mix de Eletricidade | D37: =IF(AND(EM_gridtype=5,GHG_EnergyModelUse=0),D26,SUMIF(B27:B36,"<>""",D27:D36)) -> 0 | E37: =IF(AND(EM_gridtype=5,GHG_EnergyModelUse=0),$D$26*P26/$S$26/(1-$T$26),SUMPRODUCT($D$27:$D$36*P27:P36/$S$27:$S$36/(1-$T$27:$T$36))) -> 0 | F37: =IF(AND(EM_gridtype=5,GHG_EnergyModelUse=0),$D$26*Q26/$S$26/(1-$T$26),SUMPRODUCT($D$27:$D$36*Q27:Q36/$S$27:$S$36/(1-$T$27:$T$36))) -> 0 | G37: =IF(AND(EM_gridtype=5,GHG_EnergyModelUse=0),$D$26*R26/$S$26/(1-$T$26),SUMPRODUCT($D$27:$D$36*R27:R36/$S$27:$S$36/(1-$T$27:$T$36))) -> 0 | J37: =IF(AND(EM_gridtype=5,GHG_EnergyModelUse=0),J26,SUMPRODUCT(D27:D36,J27:J36)) -> 0 | K37: =IF(AND(EM_gridtype=5,GHG_EnergyModelUse=0),K26,SUMPRODUCT(D27:D36,K27:K36)) -> 0 | AB37: 92000
AB38: 92000
AB39: 92000
B40: =IF(Q43=5,C13,Language!C631) -> País - região | E40: =C13 -> Tipo de Combustível | F40: =Language!C597 -> Fator de Emissão de GEE (excl. T&D) | G40: =J12 -> Perdas T&D | H40: =Language!C596 -> Fator de emissão de GEE | AB40: 92000
...

Sheet Análise Financeira
A1: =Language!C2603&'Análise de Emissões'!B188 -> Análise Financeira RETScreen -Projeto produção de Eletricidade | T1: =HideCode_projectType -> 2 | U1: project type | V1: =IF(OR(Iniciar!O26=1,Iniciar!O26=3),1,2) -> 1 | W1: Grid type | AB1: 0 | AC1: -93.996927 | BG1: 70000 | BH1: 70000 | BI1: 70000 | BM1: Checbox | BN1: row | BO1: columns | BP1: link row | BQ1: link column | BR1: srow | BS1: scolumn
T2: =GHG -> 139 | U2: GHG use | BA2: ='Análise de Custos'!E254 -> 10 | BB2: ='Análise de Custos'!E255 -> 0 | BG2: 70000 | BH2: 70000 | BI2: 70000 | BN2: 20 | BO2: 4 | BP2: 81 | BQ2: 21 | BR2: 20 | BS2: 3
A3: =Language!C647 -> Parâmetros financeiros | F3: =Language!C682 -> Custo projeto e sumario econ./receita | M3: =Language!C642 -> Fluxo de caixa anual | T3: Cash Outflows | AA3: Cash Inflows | AH3: Net Cash Flows | AJ3: Tax Analysis | AR3: Taxes | AS3: Taxes | AU3: Taxes | AW3: Debt Service Coverage Analysis | BA3: Periodic Costs (Credits) | BG3: 72000 | BH3: 74000 | BI3: 76000 | BN3: 38 | BO3: 4 | BP3: 84 | BQ3: 21 | BR3: 38 | BS3: 3
